Workbook
Name Slicer_Age_Group: #N/A
Name Slicer_Age_Group1: #N/A
Name Slicer_Age_Group2: #N/A
Name Slicer_Country: #N/A
Name Slicer_Country1: #N/A
Name Slicer_Favorite_Genre: #N/A
Name Slicer_Favorite_Genre1: #N/A
Name Slicer_Membership_Status: #N/A

Sheet Raw Data
A1: User_ID | B1: User_Name | C1: Join_Date | D1: Last_Login | E1: Monthly_Price | F1: Watch_Hours | G1: Favorite_Genre | H1: Active_Devices | I1: Profile_Count | J1: Parental_Controls | K1: Total_Movies_Watched | L1: Total_Series_Watched | M1: Country | N1: Payment_Method | O1: Language_Preference | P1: Recommended_Content_Count | Q1: Average_Rating_Given | R1: Has_Downloaded_Content | S1: Membership_Status | T1: Loyalty_Points | U1: First_Device_Used | V1: Age_Group | W1: Primary_Watch_Time
A2: 2518 | B2: Amber | C2: 45061 | D2: 45639 | E2: 7.99 | F2: 49 | G2: Action | H2: 3 | I2: 6 | J2: TRUE | K2: 641 | L2: 117 | M2: USA | N2: PayPal | O2: Hindi | P2: 84 | Q2: 3.3 | R2: FALSE | S2: Active | T2: 2878 | U2: Smartphone | V2: 35-44 | W2: Late Night
A3: 6430 | B3: Patrick | C3: 45019 | D3: 45641 | E3: 7.99 | F3: 161 | G3: Drama | H3: 1 | I3: 2 | J3: TRUE | K3: 192 | L3: 65 | M3: USA | N3: PayPal | O3: German | P3: 69 | Q3: 4 | R3: FALSE | S3: Active | T3: 2291 | U3: Desktop | V3: 25-34 | W3: Evening
A4: 1798 | B4: Robert | C4: 45140 | D4: 45640 | E4: 11.99 | F4: 87 | G4: Action | H4: 2 | I4: 5 | J4: FALSE | K4: 260 | L4: 127 | M4: Canada | N4: Debit Card | O4: Mandarin | P4: 56 | Q4: 3.1 | R4: FALSE | S4: Active | T4: 1692 | U4: Desktop | V4: 35-44 | W4: Late Night
A5: 5255 | B5: Cole | C5: 44957 | D5: 45628 | E5: 15.99 | F5: 321 | G5: Sci-Fi | H5: 1 | I5: 5 | J5: FALSE | K5: 61 | L5: 192 | M5: UK | N5: Debit Card | O5: Mandarin | P5: 47 | Q5: 4.6 | R5: FALSE | S5: Active | T5: 952 | U5: Desktop | V5: 25-34 | W5: Evening
A6: 2854 | B6: Jamie | C6: 45083 | D6: 45641 | E6: 11.99 | F6: 386 | G6: Documentary | H6: 1 | I6: 4 | J6: TRUE | K6: 230 | L6: 2 | M6: USA | N6: PayPal | O6: Mandarin | P6: 39 | Q6: 3.7 | R6: FALSE | S6: Active | T6: 1823 | U6: Desktop | V6: 25-34 | W6: Late Night
A7: 6735 | B7: Mary | C7: 45186 | D7: 45615 | E7: 15.99 | F7: 408 | G7: Documentary | H7: 2 | I7: 6 | J7: TRUE | K7: 837 | L7: 105 | M7: India | N7: Credit Card | O7: Spanish | P7: 71 | Q7: 4.3 | R7: TRUE | S7: Active | T7: 33 | U7: Smart TV | V7: 18-24 | W7: Morning
A8: 2995 | B8: Theodore | C8: 45529 | D8: 45636 | E8: 7.99 | F8: 475 | G8: Horror | H8: 5 | I8: 4 | J8: TRUE | K8: 510 | L8: 143 | M8: USA | N8: Credit Card | O8: English | P8: 1 | Q8: 4.5 | R8: FALSE | S8: Active | T8: 755 | U8: Laptop | V8: 35-44 | W8: Late Night
A9: 5120 | B9: Olivia | C9: 45443 | D9: 45640 | E9: 15.99 | F9: 258 | G9: Action | H9: 4 | I9: 1 | J9: TRUE | K9: 907 | L9: 47 | M9: Australia | N9: Debit Card | O9: Hindi | P9: 32 | Q9: 3.7 | R9: TRUE | S9: Active | T9: 2866 | U9: Smartphone | V9: 45-54 | W9: Late Night
A10: 6063 | B10: Patricia | C10: 45094 | D10: 45643 | E10: 15.99 | F10: 183 | G10: Comedy | H10: 5 | I10: 2 | J10: TRUE | K10: 676 | L10: 61 | M10: Germany | N10: Cryptocurrency | O10: Mandarin | P10: 26 | Q10: 3.3 | R10: TRUE | S10: Active | T10: 336 | U10: Tablet | V10: 25-34 | W10: Late Night
A11: 6896 | B11: Linda | C11: 45262 | D11: 45640 | E11: 7.99 | F11: 164 | G11: Documentary | H11: 5 | I11: 4 | J11: TRUE | K11: 406 | L11: 79 | M11: USA | N11: Credit Card | O11: French | P11: 90 | Q11: 3.2 | R11: FALSE | S11: Active | T11: 3898 | U11: Laptop | V11: 55+ | W11: Late Night
A12: 8447 | B12: Nichole | C12: 45013 | D12: 45618 | E12: 11.99 | F12: 411 | G12: Comedy | H12: 5 | I12: 4 | J12: TRUE | K12: 352 | L12: 78 | M12: UK | N12: Credit Card | O12: English | P12: 47 | Q12: 3.7 | R12: FALSE | S12: Active | T12: 650 | U12: Tablet | V12: 55+ | W12: Late Night
A13: 1433 | B13: Frances | C13: 45353 | D13: 45616 | E13: 15.99 | F13: 160 | G13: Drama | H13: 5 | I13: 6 | J13: TRUE | K13: 391 | L13: 132 | M13: Canada | N13: Debit Card | O13: German | P13: 57 | Q13: 3 | R13: FALSE | S13: Active | T13: 185 | U13: Laptop | V13: 35-44 | W13: Late Night
... A1001: 5320 | B1001: Katherine | C1001: 45197 | D1001: 45635 | E1001: 11.99 | F1001: 123 | G1001: Documentary | H1001: 1 | I1001: 6 | J1001: FALSE | K1001: 718 | L1001: 25 | M1001: USA | N1001: PayPal | O1001: German | P1001: 73 | Q1001: 4.4 | R1001: FALSE | S1001: Active | T1001: 3179 | U1001: Smart TV | V1001: 25-34 | W1001: Morning

Sheet Calculated_Fields
A1: Membership_Age | B1: Revenue_Category | C1: Monthly_Price | D1: User_ID | E1: Favorite_Genre | F1: Age_Group | G1: Watch_Hours | H1: Membership_Status | I1: Loyalty_Points | J1: User_ID | K1: Country | L1: Payment_Method | M1: Total_Movies_Watched | N1: Total_Series_Watched | O1: Age_Group | P1: Country | Q1: Watch_Hours | R1: Language_Preference | S1: Monthly_Price | T1: Average Revenue Per User
A2: ='Raw Data'!D2-'Raw Data'!C2 -> 578 | B2: =_xlfn.IFS('Raw Data'!E2>10,"Premium",'Raw Data'!E2<10,"Basic") -> Basic | C2: 7.99 | D2: 2518 | E2: Action | F2: 35-44 | G2: 49 | H2: Active | I2: 2878 | J2: 2518 | K2: USA | L2: PayPal | M2: 641 | N2: 117 | O2: 35-44 | P2: USA | Q2: 49 | R2: Hindi | S2: 7.99
A3: ='Raw Data'!D3-'Raw Data'!C3 -> 622 | B3: =_xlfn.IFS('Raw Data'!E3>10,"Premium",'Raw Data'!E3<10,"Basic") -> Basic | C3: 7.99 | D3: 6430 | E3: Drama | F3: 25-34 | G3: 161 | H3: Active | I3: 2291 | J3: 6430 | K3: USA | L3: PayPal | M3: 192 | N3: 65 | O3: 25-34 | P3: USA | Q3: 161 | R3: German | S3: 7.99
A4: ='Raw Data'!D4-'Raw Data'!C4 -> 500 | B4: =_xlfn.IFS('Raw Data'!E4>10,"Premium",'Raw Data'!E4<10,"Basic") -> Premium | C4: 11.99 | D4: 1798 | E4: Action | F4: 35-44 | G4: 87 | H4: Active | I4: 1692 | J4: 1798 | K4: Canada | L4: Debit Card | M4: 260 | N4: 127 | O4: 35-44 | P4: Canada | Q4: 87 | R4: Mandarin | S4: 11.99
A5: ='Raw Data'!D5-'Raw Data'!C5 -> 671 | B5: =_xlfn.IFS('Raw Data'!E5>10,"Premium",'Raw Data'!E5<10,"Basic") -> Premium | C5: 15.99 | D5: 5255 | E5: Sci-Fi | F5: 25-34 | G5: 321 | H5: Active | I5: 952 | J5: 5255 | K5: UK | L5: Debit Card | M5: 61 | N5: 192 | O5: 25-34 | P5: UK | Q5: 321 | R5: Mandarin | S5: 15.99
A6: ='Raw Data'!D6-'Raw Data'!C6 -> 558 | B6: =_xlfn.IFS('Raw Data'!E6>10,"Premium",'Raw Data'!E6<10,"Basic") -> Premium | C6: 11.99 | D6: 2854 | E6: Documentary | F6: 25-34 | G6: 386 | H6: Active | I6: 1823 | J6: 2854 | K6: USA | L6: PayPal | M6: 230 | N6: 2 | O6: 25-34 | P6: USA | Q6: 386 | R6: Mandarin | S6: 11.99
A7: ='Raw Data'!D7-'Raw Data'!C7 -> 429 | B7: =_xlfn.IFS('Raw Data'!E7>10,"Premium",'Raw Data'!E7<10,"Basic") -> Premium | C7: 15.99 | D7: 6735 | E7: Documentary | F7: 18-24 | G7: 408 | H7: Active | I7: 33 | J7: 6735 | K7: India | L7: Credit Card | M7: 837 | N7: 105 | O7: 18-24 | P7: India | Q7: 408 | R7: Spanish | S7: 15.99
A8: ='Raw Data'!D8-'Raw Data'!C8 -> 107 | B8: =_xlfn.IFS('Raw Data'!E8>10,"Premium",'Raw Data'!E8<10,"Basic") -> Basic | C8: 7.99 | D8: 2995 | E8: Horror | F8: 35-44 | G8: 475 | H8: Active | I8: 755 | J8: 2995 | K8: USA | L8: Credit Card | M8: 510 | N8: 143 | O8: 35-44 | P8: USA | Q8: 475 | R8: English | S8: 7.99
A9: ='Raw Data'!D9-'Raw Data'!C9 -> 197 | B9: =_xlfn.IFS('Raw Data'!E9>10,"Premium",'Raw Data'!E9<10,"Basic") -> Premium | C9: 15.99 | D9: 5120 | E9: Action | F9: 45-54 | G9: 258 | H9: Active | I9: 2866 | J9: 5120 | K9: Australia | L9: Debit Card | M9: 907 | N9: 47 | O9: 45-54 | P9: Australia | Q9: 258 | R9: Hindi | S9: 15.99
A10: ='Raw Data'!D10-'Raw Data'!C10 -> 549 | B10: =_xlfn.IFS('Raw Data'!E10>10,"Premium",'Raw Data'!E10<10,"Basic") -> Premium | C10: 15.99 | D10: 6063 | E10: Comedy | F10: 25-34 | G10: 183 | H10: Active | I10: 336 | J10: 6063 | K10: Germany | L10: Cryptocurrency | M10: 676 | N10: 61 | O10: 25-34 | P10: Germany | Q10: 183 | R10: Mandarin | S10: 15.99
A11: ='Raw Data'!D11-'Raw Data'!C11 -> 378 | B11: =_xlfn.IFS('Raw Data'!E11>10,"Premium",'Raw Data'!E11<10,"Basic") -> Basic | C11: 7.99 | D11: 6896 | E11: Documentary | F11: 55+ | G11: 164 | H11: Active | I11: 3898 | J11: 6896 | K11: USA | L11: Credit Card | M11: 406 | N11: 79 | O11: 55+ | P11: USA | Q11: 164 | R11: French | S11: 7.99
A12: ='Raw Data'!D12-'Raw Data'!C12 -> 605 | B12: =_xlfn.IFS('Raw Data'!E12>10,"Premium",'Raw Data'!E12<10,"Basic") -> Premium | C12: 11.99 | D12: 8447 | E12: Comedy | F12: 55+ | G12: 411 | H12: Active | I12: 650 | J12: 8447 | K12: UK | L12: Credit Card | M12: 352 | N12: 78 | O12: 55+ | P12: UK | Q12: 411 | R12: English | S12: 11.99
A13: ='Raw Data'!D13-'Raw Data'!C13 -> 263 | B13: =_xlfn.IFS('Raw Data'!E13>10,"Premium",'Raw Data'!E13<10,"Basic") -> Premium | C13: 15.99 | D13: 1433 | E13: Drama | F13: 35-44 | G13: 160 | H13: Active | I13: 185 | J13: 1433 | K13: Canada | L13: Debit Card | M13: 391 | N13: 132 | O13: 35-44 | P13: Canada | Q13: 160 | R13: German | S13: 15.99
... A1001: ='Raw Data'!D1001-'Raw Data'!C1001 -> 438 | B1001: =_xlfn.IFS('Raw Data'!E1001>10,"Premium",'Raw Data'!E1001<10,"Basic") -> Premium | C1001: 11.99 | D1001: 5320 | E1001: Documentary | F1001: 25-34 | G1001: 123 | H1001: Active | I1001: 3179 | J1001: 5320 | K1001: USA | L1001: PayPal | M1001: 718 | N1001: 25 | O1001: 25-34 | P1001: USA | Q1001: 123 | R1001: German | S1001: 11.99

Sheet Pivot_Tables 
A1: Revenue_Category | B1: Total Users | C1: Total Revenue | D1: Average Revenue Per User | G1: Subscription & Revenue
A2: Basic | B2: 323 | C2: 2580.77 | D2: =GETPIVOTDATA("Total Revenue",$A$1,"Revenue_Category","Basic")/GETPIVOTDATA("Total Users",$A$1,"Revenue_Category","Basic") -> 7.99
A3: Premium | B3: 677 | C3: 9445.23 | D3: =GETPIVOTDATA("Total Revenue",$A$1,"Revenue_Category","Premium")/GETPIVOTDATA("Total Users",$A$1,"Revenue_Category","Premium") -> 13.951595
A4: Grand Total | B4: 1000 | C4: 12026
A6: Age_Group | B6: (All) | Q6: Total Movies vs. Series Watched per User | V6: Impact of recommended content on engagement
A7: Engagement Metrics | Q7: Age Group | R7: Sum of Total_Series_Watched | S7: Sum of Total_Movies_Watched | V7: Recommended_Content_Count | W7: Average of Watch_Hours
A8: Favorit_Genre | B8: Average of Watch_Hours | H8: Total Revenue | I8: Average Revenue Per User | Q8: 18-24 | R8: 19790 | S8: 94100 | V8: 0 | W8: 277.81818
A9: Action | B9: 242.91333 | H9: 2580.77 | I9: =GETPIVOTDATA("Total Revenue",$A$1,"Revenue_Category","Basic")/GETPIVOTDATA("Total Users",$A$1,"Revenue_Category","Basic") -> 7.99 | Q9: 25-34 | R9: 18631 | S9: 100542 | V9: 1 | W9: 325.14286
A10: Comedy | B10: 263.43836 | H10: 9445.23 | I10: =GETPIVOTDATA("Total Revenue",$A$1,"Revenue_Category","Premium")/GETPIVOTDATA("Total Users",$A$1,"Revenue_Category","Premium") -> 13.951595 | Q10: 35-44 | R10: 20452 | S10: 110132 | V10: 2 | W10: 371.2
A11: Documentary | B11: 260.09231 | Q11: 45-54 | R11: 22023 | S11: 104205 | V11: 3 | W11: 233.73333
A12: Drama | B12: 249.56338 | Q12: 55+ | R12: 18850 | S12: 106918 | V12: 4 | W12: 320.22222
A13: Horror | B13: 256.32484 | Q13: (blank) | V13: 5 | W13: 324
A14: Romance | B14: 258.15068 | Q14: Grand Total | R14: 99746 | S14: 515897 | V14: 6 | W14: 272.5
A15: Sci-Fi | B15: 251.42636 | V15: 7 | W15: 276.16667
A16: (blank) | V16: 8 | W16: 219.85714
A17: Grand Total | B17: 254.516 | V17: 9 | W17: 234.16667
V18: 10 | W18: 259.5
V19: 11 | W19: 229.94118
A20: Demographics | V20: 12 | W20: 320.5
A21: Count of User_ID | B21: Favorite_Genre | K21: Device Usage Trends | V21: 13 | W21: 226.54545
A22: Age_Group | B22: Action | C22: Comedy | D22: Documentary | E22: Drama | F22: Horror | G22: Romance | H22: Sci-Fi | I22: Grand Total | K22: First Device Used | L22: Count of User_ID | R22: Peak watch time trends (Morning, Evening, Late Night). | V22: 14 | W22: 255.58333
A23: 18-24 | B23: 26 | C23: 23 | D23: 36 | E23: 25 | F23: 23 | G23: 24 | H23: 23 | I23: 180 | K23: Desktop | L23: 189 | M23: =GETPIVOTDATA("User_ID",$K$22,"First_Device_Used","Desktop")/GETPIVOTDATA("User_ID",$K$22) -> 0.189 | R23: Primary Watch Timecd | S23: Average of Watch_Hours | V23: 15 | W23: 335.57143
A24: 25-34 | B24: 33 | C24: 29 | D24: 21 | E24: 31 | F24: 36 | G24: 27 | H24: 23 | I24: 200 | K24: Laptop | L24: 178 | M24: =GETPIVOTDATA("User_ID",$K$22,"First_Device_Used","Laptop")/GETPIVOTDATA("User_ID",$K$22) -> 0.178 | R24: Afternoon | S24: 247.07968 | V24: 16 | W24: 152.33333
A25: 35-44 | B25: 32 | C25: 29 | D25: 22 | E25: 27 | F25: 34 | G25: 32 | H25: 31 | I25: 207 | K25: Smart TV | L25: 209 | M25: =GETPIVOTDATA("User_ID",$K$22,"First_Device_Used","Smart TV")/GETPIVOTDATA("User_ID",$K$22) -> 0.209 | R25: Evening | S25: 255.39453 | V25: 17 | W25: 187.81818
A26: 45-54 | B26: 34 | C26: 26 | D26: 22 | E26: 31 | F26: 32 | G26: 36 | H26: 27 | I26: 208 | K26: Smartphone | L26: 209 | M26: =GETPIVOTDATA("User_ID",$K$22,"First_Device_Used","Smartphone")/GETPIVOTDATA("User_ID",$K$22) -> 0.209 | R26: Late Night | S26: 245.98155 | V26: 18 | W26: 240.5
A27: 55+ | B27: 25 | C27: 39 | D27: 29 | E27: 28 | F27: 32 | G27: 27 | H27: 25 | I27: 205 | K27: Tablet | L27: 215 | M27: =GETPIVOTDATA("User_ID",$K$22,"First_Device_Used","Tablet")/GETPIVOTDATA("User_ID",$K$22) -> 0.215 | R27: Morning | S27: 272.32883 | V27: 19 | W27: 299.16667
A28: Grand Total | B28: 150 | C28: 146 | D28: 130 | E28: 142 | F28: 157 | G28: 146 | H28: 129 | I28: 1000 | K28: Grand Total | L28: 1000 | R28: Grand Total | S28: 254.516 | V28: 20 | W28: 225
V29: 21 | W29: 166.71429
A30: Retention & Loyalty | K30: Loyalty Points Distribution | V30: 22 | W30: 335.2
A31: Row Labels | B31: Count of User_ID | C31: Average of Loyalty_Points | V31: 23 | W31: 188.4
A32: Active | B32: 1000 | C32: 2444.217 | P32: Frequency of Logins and Content Downloads | V32: 24 | W32: 268
A33: Inactive | P33: Count of User_ID | Q33: Membership_Status | V33: 25 | W33: 181
A34: Grand Total | B34: 1000 | C34: 2444.217 | P34: Has Download the Content | Q34: Active | R34: Grand Total | V34: 26 | W34: 212.71429
P35: FALSE | Q35: 501 | R35: 501 | V35: 27 | W35: 246.375
P36: TRUE | Q36: 499 | R36: 499 | V36: 28 | W36: 302.42857
P37: Grand Total | Q37: 1000 | R37: 1000 | V37: 29 | W37: 261.71429
V38: 30 | W38: 227.09091
V39: 31 | W39: 259.72727
V40: 32 | W40: 217
V41: 33 | W41: 265.85714
...

Sheet Dashboard
I1: Streaming Services Dashboard
